<?xml version="1.0" ?>
<!-- =================================================================================== -->
<!-- |    This document was autogenerated by xacro from first_model.urdf.xacro         | -->
<!-- |    EDITING THIS FILE BY HAND IS NOT RECOMMENDED                                 | -->
<!-- =================================================================================== -->
<robot name="hybrid_robot">
  <material name="black">
    <color rgba="0 0 0 1"/>
  </material>
  <link name="base">
    <visual>
      <geometry>
        <box size="1 0.5  0.1"/>
      </geometry>
      <material name="black"/>
    </visual>
    <collision>
      <geometry>
        <box size="1 0.5  0.1"/>
      </geometry>
    </collision>
    <inertial>
      <mass value="10"/>
      <inertia ixx="0.21666666666666667" ixy="0" ixz="0" iyy="0.8416666666666667" iyz="0" izz="1.0416666666666665"/>
    </inertial>
  </link>
  <link name="extension">
    <visual>
      <geometry>
        <box size="1 0.45 0.095"/>
      </geometry>
      <material name="black"/>
    </visual>
    <collision>
      <geometry>
        <box size="1 0.45 0.095"/>
      </geometry>
    </collision>
    <inertial>
      <mass value="10"/>
      <inertia ixx="0.9208333333333332" ixy="0" ixz="0" iyy="1.5854166666666663" iyz="0" izz="1.0020833333333334"/>
    </inertial>
  </link>
  <joint name="extension_base_joint" type="prismatic">
    <axis xyz="1 0 0"/>
    <parent link="base"/>
    <child link="extension"/>
    <origin xyz="-.1 0 0"/>
    <limit effort="100" lower="0" upper="1" velocity="10"/>
  </joint>
  <link name="front_right_wheel">
    <visual>
      <geometry>
        <cylinder length="0.02" radius="0.15"/>
      </geometry>
      <material name="black"/>
    </visual>
    <collision>
      <geometry>
        <cylinder length="0.02" radius="0.15"/>
      </geometry>
    </collision>
    <inertial>
      <mass value="1"/>
      <inertia ixx="1.0" ixy="0.0" ixz="0.0" iyy="1.0" iyz="0.0" izz="1.0"/>
    </inertial>
  </link>
  <joint name="front_right_wheel_joint" type="continuous">
    <axis rpy="0 0 0" xyz="0 1 0"/>
    <parent link="base"/>
    <child link="front_right_wheel"/>
    <origin rpy="1.5707963267948966 0 0" xyz="0.45 -0.26 0"/>
  </joint>
  <link name="front_left_wheel">
    <visual>
      <geometry>
        <cylinder length="0.02" radius="0.15"/>
      </geometry>
      <material name="black"/>
    </visual>
    <collision>
      <geometry>
        <cylinder length="0.02" radius="0.15"/>
      </geometry>
    </collision>
    <inertial>
      <mass value="1"/>
      <inertia ixx="1.0" ixy="0.0" ixz="0.0" iyy="1.0" iyz="0.0" izz="1.0"/>
    </inertial>
  </link>
  <joint name="front_left_wheel_joint" type="continuous">
    <axis rpy="0 0 0" xyz="0 1 0"/>
    <parent link="base"/>
    <child link="front_left_wheel"/>
    <origin rpy="1.5707963267948966 0 0" xyz="0.45 0.26 0"/>
  </joint>
  <link name="back_right_wheel">
    <visual>
      <geometry>
        <cylinder length="0.02" radius="0.15"/>
      </geometry>
      <material name="black"/>
    </visual>
    <collision>
      <geometry>
        <cylinder length="0.02" radius="0.15"/>
      </geometry>
    </collision>
    <inertial>
      <mass value="1"/>
      <inertia ixx="1.0" ixy="0.0" ixz="0.0" iyy="1.0" iyz="0.0" izz="1.0"/>
    </inertial>
  </link>
  <joint name="back_right_wheel_joint" type="continuous">
    <axis rpy="0 0 0" xyz="0 1 0"/>
    <parent link="extension"/>
    <child link="back_right_wheel"/>
    <origin rpy="1.5707963267948966 0 0" xyz="-0.45 -0.26 0"/>
  </joint>
  <link name="back_left_wheel">
    <visual>
      <geometry>
        <cylinder length="0.02" radius="0.15"/>
      </geometry>
      <material name="black"/>
    </visual>
    <collision>
      <geometry>
        <cylinder length="0.02" radius="0.15"/>
      </geometry>
    </collision>
    <inertial>
      <mass value="1"/>
      <inertia ixx="1.0" ixy="0.0" ixz="0.0" iyy="1.0" iyz="0.0" izz="1.0"/>
    </inertial>
  </link>
  <joint name="back_left_wheel_joint" type="continuous">
    <axis rpy="0 0 0" xyz="0 1 0"/>
    <parent link="extension"/>
    <child link="back_left_wheel"/>
    <origin rpy="1.5707963267948966 0 0" xyz="-0.45 0.26 0"/>
  </joint>
</robot>

